Workbook

Sheet Flotte IJN
A1: Navire | G1: Indemne | K1: Dommages significatifs | O1: Écart (endommagé − indemne)
A2: Navire | B2: Nom japonais | C2: Type | D2: Type (libellé) | E2: ⊗ | F2: Carrier/Base | G2: Anti-air | H2: Durabilité | I2: Puissance de feu | J2: Fichier | K2: Anti-air | L2: Durabilité | M2: Puissance de feu | N2: Fichier | O2: Anti-air | P2: Durabilité | Q2: Puissance de feu
A3: AKAGI | B3: 赤城 | C3: CV | D3: Porte-avions | F3: AKA | G3: 3 | H3: 5 | I3: 0 | J3: CF4 (9).png | K3: 2 | L3: 4 | M3: 0 | N3: CB4 (13).png | O3: =IF(K3="","",IFERROR(K3-G3,"—")) | P3: =IF(L3="","",IFERROR(L3-H3,"—")) | Q3: =IF(M3="","",IFERROR(M3-I3,"—"))
A4: HIRYŪ | B4: 飛龍 | C4: CV | D4: Porte-avions | F4: HIR | G4: 3 | H4: 4 | I4: 0 | J4: CF4 (10).png | K4: 2 | L4: 4 | M4: 0 | N4: CB4 (12).png | O4: =IF(K4="","",IFERROR(K4-G4,"—")) | P4: =IF(L4="","",IFERROR(L4-H4,"—")) | Q4: =IF(M4="","",IFERROR(M4-I4,"—"))
A5: KAGA | B5: 加賀 | C5: CV | D5: Porte-avions | F5: KA | G5: 3 | H5: 5 | I5: 0 | J5: CF4 (11).png | K5: 2 | L5: 4 | M5: 0 | N5: CB4 (11).png | O5: =IF(K5="","",IFERROR(K5-G5,"—")) | P5: =IF(L5="","",IFERROR(L5-H5,"—")) | Q5: =IF(M5="","",IFERROR(M5-I5,"—"))
A6: SHŌKAKU | B6: 翔鶴 | C6: CV | D6: Porte-avions | F6: SHO | G6: 3 | H6: 4 | I6: 0 | J6: CF4 (12).png | K6: 3 | L6: 4 | M6: 0 | N6: CB4 (10).png | O6: =IF(K6="","",IFERROR(K6-G6,"—")) | P6: =IF(L6="","",IFERROR(L6-H6,"—")) | Q6: =IF(M6="","",IFERROR(M6-I6,"—"))
A7: SŌRYŪ | B7: 蒼龍 | C7: CV | D7: Porte-avions | F7: SOR | G7: 3 | H7: 4 | I7: 0 | J7: CF4 (13).png | K7: 2 | L7: 3 | M7: 0 | N7: CB4 (9).png | O7: =IF(K7="","",IFERROR(K7-G7,"—")) | P7: =IF(L7="","",IFERROR(L7-H7,"—")) | Q7: =IF(M7="","",IFERROR(M7-I7,"—"))
A8: ZUIKAKU | B8: 瑞鶴 | C8: CV | D8: Porte-avions | F8: ZUI | G8: 3 | H8: 4 | I8: 0 | J8: CF4 (14).png | K8: 3 | L8: 4 | M8: 0 | N8: CB4 (8).png | O8: =IF(K8="","",IFERROR(K8-G8,"—")) | P8: =IF(L8="","",IFERROR(L8-H8,"—")) | Q8: =IF(M8="","",IFERROR(M8-I8,"—"))
A9: HIYŌ | B9: 飛鷹 | C9: CVL | D9: Porte-avions léger | G9: 3 | H9: 3 | I9: 0 | J9: CF4 (15).png | K9: 2 | L9: 3 | M9: 0 | N9: CB4 (21).png | O9: =IF(K9="","",IFERROR(K9-G9,"—")) | P9: =IF(L9="","",IFERROR(L9-H9,"—")) | Q9: =IF(M9="","",IFERROR(M9-I9,"—"))
A10: JUN'YŌ | B10: 隼鷹 | C10: CVL | D10: Porte-avions léger | G10: 3 | H10: 3 | I10: 0 | J10: CF4 (16).png | K10: 2 | L10: 3 | M10: 0 | N10: CB4 (20).png | O10: =IF(K10="","",IFERROR(K10-G10,"—")) | P10: =IF(L10="","",IFERROR(L10-H10,"—")) | Q10: =IF(M10="","",IFERROR(M10-I10,"—"))
A11: RYŪJŌ | B11: 龍驤 | C11: CVL | D11: Porte-avions léger | G11: 3 | H11: 3 | I11: 0 | J11: CF4 (17).png | K11: 2 | L11: 2 | M11: 0 | N11: CB4 (19).png | O11: =IF(K11="","",IFERROR(K11-G11,"—")) | P11: =IF(L11="","",IFERROR(L11-H11,"—")) | Q11: =IF(M11="","",IFERROR(M11-I11,"—"))
A12: SHŌHŌ | B12: 祥鳳 | C12: CVL | D12: Porte-avions léger | G12: 3 | H12: 3 | I12: 0 | J12: CF4 (18).png | K12: 2 | L12: 2 | M12: 0 | N12: CB4 (18).png | O12: =IF(K12="","",IFERROR(K12-G12,"—")) | P12: =IF(L12="","",IFERROR(L12-H12,"—")) | Q12: =IF(M12="","",IFERROR(M12-I12,"—"))
A13: UN'YŌ | B13: 雲鷹 | C13: CVL | D13: Porte-avions léger | G13: 3 | H13: 3 | I13: 0 | J13: CF4 (19).png | K13: 1 | L13: 2 | M13: 0 | N13: CB4 (17).png | O13: =IF(K13="","",IFERROR(K13-G13,"—")) | P13: =IF(L13="","",IFERROR(L13-H13,"—")) | Q13: =IF(M13="","",IFERROR(M13-I13,"—"))
A14: ZUIHŌ | B14: 瑞鳳 | C14: CVL | D14: Porte-avions léger | G14: 3 | H14: 3 | I14: 0 | J14: CF4 (20).png | K14: 2 | L14: 2 | M14: 0 | N14: CB4 (16).png | O14: =IF(K14="","",IFERROR(K14-G14,"—")) | P14: =IF(L14="","",IFERROR(L14-H14,"—")) | Q14: =IF(M14="","",IFERROR(M14-I14,"—"))
A15: FUSŌ | B15: 扶桑 | C15: BB | D15: Cuirassé | E15: ⊗ | G15: 3 | H15: 7 | I15: 9 | J15: CF4 (21).png | K15: 2 | L15: 7 | M15: 7 | N15: CB4 (15).png | O15: =IF(K15="","",IFERROR(K15-G15,"—")) | P15: =IF(L15="","",IFERROR(L15-H15,"—")) | Q15: =IF(M15="","",IFERROR(M15-I15,"—"))
A16: HARUNA | B16: 榛名 | C16: BB | D16: Cuirassé | G16: 3 | H16: 7 | I16: 8 | J16: CF4 (22).png | K16: 2 | L16: 7 | M16: 7 | N16: CB4 (28).png | O16: =IF(K16="","",IFERROR(K16-G16,"—")) | P16: =IF(L16="","",IFERROR(L16-H16,"—")) | Q16: =IF(M16="","",IFERROR(M16-I16,"—"))
A17: HIEI | B17: 比叡 | C17: BB | D17: Cuirassé | G17: 3 | H17: 7 | I17: 8 | J17: CF4 (23).png | K17: 2 | L17: 7 | M17: 7 | N17: CB4 (27).png | O17: =IF(K17="","",IFERROR(K17-G17,"—")) | P17: =IF(L17="","",IFERROR(L17-H17,"—")) | Q17: =IF(M17="","",IFERROR(M17-I17,"—"))
A18: HYŪGA | B18: 日向 | C18: BB | D18: Cuirassé | E18: ⊗ | G18: 3 | H18: 8 | I18: 9 | J18: CF4 (24).png | K18: 2 | L18: 7 | M18: 7 | N18: CB4 (26).png | O18: =IF(K18="","",IFERROR(K18-G18,"—")) | P18: =IF(L18="","",IFERROR(L18-H18,"—")) | Q18: =IF(M18="","",IFERROR(M18-I18,"—"))
A19: ISE | B19: 伊勢 | C19: BB | D19: Cuirassé | E19: ⊗ | G19: 3 | H19: 8 | I19: 9 | J19: CF4 (25).png | K19: 2 | L19: 7 | M19: 7 | N19: CB4 (25).png | O19: =IF(K19="","",IFERROR(K19-G19,"—")) | P19: =IF(L19="","",IFERROR(L19-H19,"—")) | Q19: =IF(M19="","",IFERROR(M19-I19,"—"))
A20: KIRISHIMA | B20: 霧島 | C20: BB | D20: Cuirassé | G20: 3 | H20: 7 | I20: 8 | J20: CF4 (26).png | K20: 2 | L20: 7 | M20: 7 | N20: CB4 (24).png | O20: =IF(K20="","",IFERROR(K20-G20,"—")) | P20: =IF(L20="","",IFERROR(L20-H20,"—")) | Q20: =IF(M20="","",IFERROR(M20-I20,"—"))
A21: KONGŌ | B21: 金剛 | C21: BB | D21: Cuirassé | G21: 3 | H21: 7 | I21: 8 | J21: CF4 (27).png | K21: 2 | L21: 7 | M21: 7 | N21: CB4 (23).png | O21: =IF(K21="","",IFERROR(K21-G21,"—")) | P21: =IF(L21="","",IFERROR(L21-H21,"—")) | Q21: =IF(M21="","",IFERROR(M21-I21,"—"))
A22: MUSASHI | B22: 武蔵 | C22: BB | D22: Cuirassé | E22: ⊗ | G22: 4 | H22: 12 | I22: 14 | J22: CF4 (28).png | K22: 3 | L22: 10 | M22: 11 | N22: CB4 (22).png | O22: =IF(K22="","",IFERROR(K22-G22,"—")) | P22: =IF(L22="","",IFERROR(L22-H22,"—")) | Q22: =IF(M22="","",IFERROR(M22-I22,"—"))
A23: MUTSU | B23: 陸奥 | C23: BB | D23: Cuirassé | E23: ⊗ | G23: 3 | H23: 9 | I23: 10 | J23: CF4 (29).png | K23: 2 | L23: 7 | M23: 8 | N23: CB4 (30).png | O23: =IF(K23="","",IFERROR(K23-G23,"—")) | P23: =IF(L23="","",IFERROR(L23-H23,"—")) | Q23: =IF(M23="","",IFERROR(M23-I23,"—"))
A24: NAGATO | B24: 長門 | C24: BB | D24: Cuirassé | E24: ⊗ | G24: 3 | H24: 9 | I24: 10 | J24: CF4 (30).png | K24: 2 | L24: 7 | M24: 8 | N24: CB4 (29).png | O24: =IF(K24="","",IFERROR(K24-G24,"—")) | P24: =IF(L24="","",IFERROR(L24-H24,"—")) | Q24: =IF(M24="","",IFERROR(M24-I24,"—"))
A25: YAMASHIRO | B25: 山城 | C25: BB | D25: Cuirassé | E25: ⊗ | G25: 3 | H25: 7 | I25: 9 | J25: CF5 (1).png | K25: 2 | L25: 7 | M25: 7 | N25: CB5 (7).png | O25: =IF(K25="","",IFERROR(K25-G25,"—")) | P25: =IF(L25="","",IFERROR(L25-H25,"—")) | Q25: =IF(M25="","",IFERROR(M25-I25,"—"))
A26: YAMATO | B26: 大和 | C26: BB | D26: Cuirassé | E26: ⊗ | G26: 4 | H26: 12 | I26: 14 | J26: CF5 (2).png | K26: 3 | L26: 10 | M26: 11 | N26: CB5 (6).png | O26: =IF(K26="","",IFERROR(K26-G26,"—")) | P26: =IF(L26="","",IFERROR(L26-H26,"—")) | Q26: =IF(M26="","",IFERROR(M26-I26,"—"))
A27: AOBA | B27: 青葉 | C27: CA | D27: Croiseur lourd | G27: 2 | H27: 4 | I27: 5 | J27: CF5 (3).png | K27: 1 | L27: 4 | M27: 4 | N27: CB5 (5).png | O27: =IF(K27="","",IFERROR(K27-G27,"—")) | P27: =IF(L27="","",IFERROR(L27-H27,"—")) | Q27: =IF(M27="","",IFERROR(M27-I27,"—"))
A28: ASHIGARA | B28: 足柄 | C28: CA | D28: Croiseur lourd | G28: 2 | H28: 5 | I28: 6 | J28: CF5 (4).png | K28: 1 | L28: 4 | M28: 4 | N28: CB5 (4).png | O28: =IF(K28="","",IFERROR(K28-G28,"—")) | P28: =IF(L28="","",IFERROR(L28-H28,"—")) | Q28: =IF(M28="","",IFERROR(M28-I28,"—"))
A29: ATAGO | B29: 愛宕 | C29: CA | D29: Croiseur lourd | G29: 2 | H29: 5 | I29: 6 | J29: CF5 (5).png | K29: 2 | L29: 4 | M29: 4 | N29: CB5 (3).png | O29: =IF(K29="","",IFERROR(K29-G29,"—")) | P29: =IF(L29="","",IFERROR(L29-H29,"—")) | Q29: =IF(M29="","",IFERROR(M29-I29,"—"))
A30: CHIKUMA | B30: 筑摩 | C30: CA | D30: Croiseur lourd | G30: 2 | H30: 5 | I30: 6 | J30: CF5 (6).png | K30: 2 | L30: 4 | M30: 4 | N30: CB5 (2).png | O30: =IF(K30="","",IFERROR(K30-G30,"—")) | P30: =IF(L30="","",IFERROR(L30-H30,"—")) | Q30: =IF(M30="","",IFERROR(M30-I30,"—"))
A31: CHŌKAI | B31: 鳥海 | C31: CA | D31: Croiseur lourd | G31: 2 | H31: 5 | I31: 6 | J31: CF5 (7).png | K31: 2 | L31: 4 | M31: 4 | N31: CB5 (1).png | O31: =IF(K31="","",IFERROR(K31-G31,"—")) | P31: =IF(L31="","",IFERROR(L31-H31,"—")) | Q31: =IF(M31="","",IFERROR(M31-I31,"—"))
A32: FURUTAKA | B32: 古鷹 | C32: CA | D32: Croiseur lourd | G32: 2 | H32: 4 | I32: 5 | J32: CF5 (8).png | K32: 1 | L32: 4 | M32: 4 | N32: CB5 (14).png | O32: =IF(K32="","",IFERROR(K32-G32,"—")) | P32: =IF(L32="","",IFERROR(L32-H32,"—")) | Q32: =IF(M32="","",IFERROR(M32-I32,"—"))
A33: HAGURO | B33: 羽黒 | C33: CA | D33: Croiseur lourd | G33: 2 | H33: 5 | I33: 6 | J33: CF5 (9).png | K33: 1 | L33: 4 | M33: 4 | N33: CB5 (13).png | O33: =IF(K33="","",IFERROR(K33-G33,"—")) | P33: =IF(L33="","",IFERROR(L33-H33,"—")) | Q33: =IF(M33="","",IFERROR(M33-I33,"—"))
A34: KAKO | B34: 加古 | C34: CA | D34: Croiseur lourd | G34: 2 | H34: 4 | I34: 5 | J34: CF5 (10).png | K34: 1 | L34: 4 | M34: 4 | N34: CB5 (12).png | O34: =IF(K34="","",IFERROR(K34-G34,"—")) | P34: =IF(L34="","",IFERROR(L34-H34,"—")) | Q34: =IF(M34="","",IFERROR(M34-I34,"—"))
A35: KINUGASA | B35: 衣笠 | C35: CA | D35: Croiseur lourd | G35: 2 | H35: 4 | I35: 5 | J35: CF5 (11).png | K35: 1 | L35: 4 | M35: 4 | N35: CB5 (11).png | O35: =IF(K35="","",IFERROR(K35-G35,"—")) | P35: =IF(L35="","",IFERROR(L35-H35,"—")) | Q35: =IF(M35="","",IFERROR(M35-I35,"—"))
A36: KUMANO | B36: 熊野 | C36: CA | D36: Croiseur lourd | G36: 2 | H36: 5 | I36: 5 | J36: CF5 (12).png | K36: 2 | L36: 4 | M36: 4 | N36: CB5 (10).png | O36: =IF(K36="","",IFERROR(K36-G36,"—")) | P36: =IF(L36="","",IFERROR(L36-H36,"—")) | Q36: =IF(M36="","",IFERROR(M36-I36,"—"))
A37: MAYA | B37: 摩耶 | C37: CA | D37: Croiseur lourd | G37: 2 | H37: 5 | I37: 6 | J37: CF5 (13).png | K37: 2 | L37: 4 | M37: 4 | N37: CB5 (9).png | O37: =IF(K37="","",IFERROR(K37-G37,"—")) | P37: =IF(L37="","",IFERROR(L37-H37,"—")) | Q37: =IF(M37="","",IFERROR(M37-I37,"—"))
A38: MIKUMA | B38: 三隈 | C38: CA | D38: Croiseur lourd | G38: 2 | H38: 5 | I38: 5 | J38: CF5 (14).png | K38: 2 | L38: 4 | M38: 4 | N38: CB5 (8).png | O38: =IF(K38="","",IFERROR(K38-G38,"—")) | P38: =IF(L38="","",IFERROR(L38-H38,"—")) | Q38: =IF(M38="","",IFERROR(M38-I38,"—"))
... A46: ISUZU | B46: 五十鈴 | C46: CL | D46: Croiseur léger | G46: 1 | H46: 3 | I46: 4 | J46: CF5 (22).png | K46: 1 | L46: 3 | M46: 3 | N46: CB5 (28).png | O46: =IF(K46="","",IFERROR(K46-G46,"—")) | P46: =IF(L46="","",IFERROR(L46-H46,"—")) | Q46: =IF(M46="","",IFERROR(M46-I46,"—"))
A47: JINTSŪ | B47: 神通 | C47: CL | D47: Croiseur léger | G47: 1 | H47: 3 | I47: 4 | J47: CF5 (23).png | N47: face manquante | O47: =IF(K47="","",IFERROR(K47-G47,"—")) | P47: =IF(L47="","",IFERROR(L47-H47,"—")) | Q47: =IF(M47="","",IFERROR(M47-I47,"—"))
...

Sheet Synthèse
A1: Synthèse par type (calculée depuis l’onglet Flotte IJN)
A3: Type | B3: Libellé | C3: Navires | D3: Faces endommagées présentes | E3: Faces endommagées manquantes
A4: CV | B4: Porte-avions | C4: =COUNTIF('Flotte IJN'!$C$3:$C$61,A4) | D4: =COUNTIFS('Flotte IJN'!$C$3:$C$61,A4,'Flotte IJN'!$N$3:$N$61,"<>face manquante") | E4: =C4-D4
A5: CVL | B5: Porte-avions léger | C5: =COUNTIF('Flotte IJN'!$C$3:$C$61,A5) | D5: =COUNTIFS('Flotte IJN'!$C$3:$C$61,A5,'Flotte IJN'!$N$3:$N$61,"<>face manquante") | E5: =C5-D5
A6: BB | B6: Cuirassé | C6: =COUNTIF('Flotte IJN'!$C$3:$C$61,A6) | D6: =COUNTIFS('Flotte IJN'!$C$3:$C$61,A6,'Flotte IJN'!$N$3:$N$61,"<>face manquante") | E6: =C6-D6
A7: CA | B7: Croiseur lourd | C7: =COUNTIF('Flotte IJN'!$C$3:$C$61,A7) | D7: =COUNTIFS('Flotte IJN'!$C$3:$C$61,A7,'Flotte IJN'!$N$3:$N$61,"<>face manquante") | E7: =C7-D7
A8: CL | B8: Croiseur léger | C8: =COUNTIF('Flotte IJN'!$C$3:$C$61,A8) | D8: =COUNTIFS('Flotte IJN'!$C$3:$C$61,A8,'Flotte IJN'!$N$3:$N$61,"<>face manquante") | E8: =C8-D8
A9: DD | B9: Destroyers | C9: =COUNTIF('Flotte IJN'!$C$3:$C$61,A9) | D9: =COUNTIFS('Flotte IJN'!$C$3:$C$61,A9,'Flotte IJN'!$N$3:$N$61,"<>face manquante") | E9: =C9-D9
A10: AK | B10: Transports | C10: =COUNTIF('Flotte IJN'!$C$3:$C$61,A10) | D10: =COUNTIFS('Flotte IJN'!$C$3:$C$61,A10,'Flotte IJN'!$N$3:$N$61,"<>face manquante") | E10: =C10-D10
A11: Total | C11: =SUM(C4:C10) | D11: =SUM(D4:D10) | E11: =SUM(E4:E10)

Sheet Légende
A1: Lecture d’un pion
A2: Type | B2: En haut à gauche (CV, CVL, BB, CA, CL, DD, AK).
A3: Anti-air | B3: En haut à droite.
A4: Durabilité | B4: En bas à gauche, chiffre blanc sur fond noir.
A5: Puissance de feu | B5: En bas à droite, chiffre noir sur fond blanc. « 4/8 » et « 2/4 » (KITAKAMI, ŌI) sont recopiés tels qu’imprimés ; l’écart n’est alors pas calculé (—).
A6: Carrier/Base | B6: Code rouge à côté de la puissance de feu, présent seulement sur les porte-avions CV (AKA, KA, SOR, HIR, SHO, ZUI). Les CVL n’en portent pas.
A7: ⊗ | B7: Symbole imprimé après « BB » sur certains cuirassés (FUSŌ, YAMASHIRO, ISE, HYŪGA, NAGATO, MUTSU, YAMATO, MUSASHI). Signification à préciser d’après la règle.
A8: Nom japonais | B8: Kanji imprimés en haut du pion.
A10: Fichiers
A11: C6F, CF4, CF5 | B11: Face indemne (indication de l’utilisateur).
A12: CB4, CB5, CB6 | B12: Face « dommages significatifs » (indication de l’utilisateur). CB6 (3) à (7) = croiseurs légers YURA, YŪBARI, TENRYŪ, TATSUTA, TAMA ; CB6 (8) = DD réduit (un seul destroyer, sert aussi de destroyer isolé) ; CB6 (29) = AK réduit.
A13: Appariement | B13: Les numéros entre parenthèses ne relient pas les deux faces : l’appariement est fait sur le nom imprimé.
A14: Faces manquantes | B14: 1 navire n’a pas de face endommagée : JINTSŪ (CB5 (27) absent).
A16: Source | B16: Valeurs relevées à la lecture des images de public/modules/coral-sea/images/counters/ijn/fleet (117 fichiers), le 15/10/2026 ; faces réduites CB6 ajoutées le 16/10/2026. Seuls les écarts et la synthèse sont des formules.
